Harness Status: OK
Found 18 tests: Fail = 10 Pass = 8
Fail Missing arguments  assert_throws: function "() => memory.grow()" did not throw
Pass Branding  
Pass Zero initial  
Pass Zero initial with valueOf  
Pass Non-zero initial  
Pass Zero initial with respected maximum  
Pass Zero initial with respected maximum grown twice  
Pass Zero initial growing too much  
Fail Out-of-range argument: undefined  assert_throws: function "() => memory.grow(value)" did not throw
Fail Out-of-range argument: NaN  assert_throws: function "() => memory.grow(value)" did not throw
Fail Out-of-range argument: Infinity  assert_throws: function "() => memory.grow(value)" threw object "RangeError: argument out of range" ("RangeError") expected object "TypeError" ("TypeError")
Fail Out-of-range argument: -Infinity  assert_throws: function "() => memory.grow(value)" threw object "RangeError: argument out of range" ("RangeError") expected object "TypeError" ("TypeError")
Fail Out-of-range argument: -1  assert_throws: function "() => memory.grow(value)" threw object "RangeError: argument out of range" ("RangeError") expected object "TypeError" ("TypeError")
Fail Out-of-range argument: 4294967296  assert_throws: function "() => memory.grow(value)" threw object "RangeError: argument out of range" ("RangeError") expected object "TypeError" ("TypeError")
Fail Out-of-range argument: 68719476736  assert_throws: function "() => memory.grow(value)" threw object "RangeError: argument out of range" ("RangeError") expected object "TypeError" ("TypeError")
Fail Out-of-range argument: "0x100000000"  assert_throws: function "() => memory.grow(value)" threw object "RangeError: argument out of range" ("RangeError") expected object "TypeError" ("TypeError")
Fail Out-of-range argument: object "[object Object]"  assert_throws: function "() => memory.grow(value)" threw object "RangeError: argument out of range" ("RangeError") expected object "TypeError" ("TypeError")
Pass Stray argument  
